<?xml version="1.0" ?>
<!-- =================================================================================== -->
<!-- |    This document was autogenerated by xacro from FINAL.xacro                    | -->
<!-- |    EDITING THIS FILE BY HAND IS NOT RECOMMENDED                                 | -->
<!-- =================================================================================== -->
<robot name="FINAL">
  <material name="silver">
    <color rgba="0.700 0.700 0.700 1.000"/>
  </material>
  <transmission name="Revolute 40_tran">
    <type>transmission_interface/SimpleTransmission</type>
    <joint name="Revolute 40">
      <hardwareInterface>hardware_interface/EffortJointInterface</hardwareInterface>
    </joint>
    <actuator name="Revolute 40_actr">
      <hardwareInterface>hardware_interface/EffortJointInterface</hardwareInterface>
      <mechanicalReduction>1</mechanicalReduction>
    </actuator>
  </transmission>
  <transmission name="Revolute 43_tran">
    <type>transmission_interface/SimpleTransmission</type>
    <joint name="Revolute 43">
      <hardwareInterface>hardware_interface/EffortJointInterface</hardwareInterface>
    </joint>
    <actuator name="Revolute 43_actr">
      <hardwareInterface>hardware_interface/EffortJointInterface</hardwareInterface>
      <mechanicalReduction>1</mechanicalReduction>
    </actuator>
  </transmission>
  <transmission name="Revolute 44_tran">
    <type>transmission_interface/SimpleTransmission</type>
    <joint name="Revolute 44">
      <hardwareInterface>hardware_interface/EffortJointInterface</hardwareInterface>
    </joint>
    <actuator name="Revolute 44_actr">
      <hardwareInterface>hardware_interface/EffortJointInterface</hardwareInterface>
      <mechanicalReduction>1</mechanicalReduction>
    </actuator>
  </transmission>
  <transmission name="Revolute 45_tran">
    <type>transmission_interface/SimpleTransmission</type>
    <joint name="Revolute 45">
      <hardwareInterface>hardware_interface/EffortJointInterface</hardwareInterface>
    </joint>
    <actuator name="Revolute 45_actr">
      <hardwareInterface>hardware_interface/EffortJointInterface</hardwareInterface>
      <mechanicalReduction>1</mechanicalReduction>
    </actuator>
  </transmission>
  <gazebo>
    <plugin filename="libgazebo_ros_control.so" name="control"/>
  </gazebo>
  <gazebo reference="base_link">
    <material>Gazebo/Silver</material>
    <mu1>0.2</mu1>
    <mu2>0.2</mu2>
    <self_collide>true</self_collide>
    <gravity>true</gravity>
  </gazebo>
  <gazebo reference="Sun_Connector_Shaft,_0.2497''_1">
    <material>Gazebo/Silver</material>
    <mu1>0.2</mu1>
    <mu2>0.2</mu2>
    <self_collide>true</self_collide>
  </gazebo>
  <gazebo reference="Planetary_Gear_Arm_Connector,1_1">
    <material>Gazebo/Silver</material>
    <mu1>0.2</mu1>
    <mu2>0.2</mu2>
    <self_collide>true</self_collide>
  </gazebo>
  <gazebo reference="Arm_1_1">
    <material>Gazebo/Silver</material>
    <mu1>0.2</mu1>
    <mu2>0.2</mu2>
    <self_collide>true</self_collide>
  </gazebo>
  <gazebo reference="Gear_1_1">
    <material>Gazebo/Silver</material>
    <mu1>0.2</mu1>
    <mu2>0.2</mu2>
    <self_collide>true</self_collide>
  </gazebo>
  <gazebo reference="Gear_3,_UPDATED_1">
    <material>Gazebo/Silver</material>
    <mu1>0.2</mu1>
    <mu2>0.2</mu2>
    <self_collide>true</self_collide>
  </gazebo>
  <gazebo reference="Manipulator3__2__1">
    <material>Gazebo/Silver</material>
    <mu1>0.2</mu1>
    <mu2>0.2</mu2>
    <self_collide>true</self_collide>
  </gazebo>
  <material name="grey">
    <color rgba="0.7 0.7 0.7 1"/>
  </material>
  <link name="world"/>
  <joint name="world_to_base" type="fixed">
    <parent link="world"/>
    <child link="base_link"/>
    <origin rpy="0 0 0" xyz="0 0 .1"/>
  </joint>
  <link name="base_link">
    <inertial>
      <mass value="1.0"/>
      <origin xyz="0 0 0"/>
      <inertia ixx="0.1" ixy="0.0" ixz="0.0" iyy="0.1" iyz="0.0" izz="0.1"/>
    </inertial>
    <visual>
      <origin rpy="0 0 0" xyz="0 0 0"/>
      <geometry>
        <mesh filename="$(find FINAL_description)/meshes/base_link.stl" scale="0.001 0.001 0.001"/>
      </geometry>
      <material name="grey"/>
    </visual>
    <collision>
      <origin rpy="0 0 0" xyz="0 0 0"/>
      <geometry>
        <mesh filename="$(find FINAL_description)/meshes/base_link.stl" scale="0.001 0.001 0.001"/>
      </geometry>
    </collision>
  </link>
  <link name="sun_connector_shaft_1">
    <inertial>
      <origin rpy="0 0 0" xyz="3.290622982432545e-13 -9.536743103555345e-09 0.0152396655965897"/>
      <mass value="0.007456676389725328"/>
      <inertia ixx="1e-06" ixy="0.0" ixz="-0.0" iyy="1e-06" iyz="0.0" izz="0.0"/>
    </inertial>
    <visual>
      <origin rpy="0 0 0" xyz="-0.0075 -0.1025 0.037395"/>
      <geometry>
        <mesh filename="$(find FINAL_description)/meshes/Sun_Connector_Shaft,_0.2497''_1.stl" scale="0.001 0.001 0.001"/>
      </geometry>
      <material name="grey"/>
    </visual>
    <collision>
      <origin rpy="0 0 0" xyz="-0.0075 -0.1025 0.037395"/>
      <geometry>
        <mesh filename="$(find FINAL_description)/meshes/Sun_Connector_Shaft,_0.2497''_1.stl" scale="0.001 0.001 0.001"/>
      </geometry>
    </collision>
  </link>
  <link name="Planetary_Gear_Arm_Connector,1_1">
    <inertial>
      <origin rpy="0 0 0" xyz="1.2191636589165e-14 -9.536743048044194e-09 0.0015295722361644247"/>
      <mass value="0.053040912421324096"/>
      <inertia ixx="1.1e-05" ixy="0.0" ixz="-0.0" iyy="1.1e-05" iyz="0.0" izz="2e-05"/>
    </inertial>
    <visual>
      <origin rpy="0 0 0" xyz="-0.0075 -0.1025 0.006915"/>
      <geometry>
        <mesh filename="$(find FINAL_description)/meshes/Planetary_Gear_Arm_Connector,1_1.stl" scale="0.001 0.001 0.001"/>
      </geometry>
      <material name="grey"/>
    </visual>
    <collision>
      <origin rpy="0 0 0" xyz="-0.0075 -0.1025 0.006915"/>
      <geometry>
        <mesh filename="$(find FINAL_description)/meshes/Planetary_Gear_Arm_Connector,1_1.stl" scale="0.001 0.001 0.001"/>
      </geometry>
    </collision>
  </link>
  <link name="Arm_1_1">
    <inertial>
      <origin rpy="0 0 0" xyz="-0.008148761484235868 -9.536743020288618e-09 0.09559783618692533"/>
      <mass value="0.9905731051115977"/>
      <inertia ixx="0.006626" ixy="0.0" ixz="0.000296" iyy="0.008233" iyz="0.0" izz="0.006574"/>
    </inertial>
    <visual>
      <origin rpy="0 0 0" xyz="-0.0075 -0.1025 0.005137"/>
      <geometry>
        <mesh filename="$(find FINAL_description)/meshes/Arm_1_1.stl" scale="0.001 0.001 0.001"/>
      </geometry>
      <material name="grey"/>
    </visual>
    <collision>
      <origin rpy="0 0 0" xyz="-0.0075 -0.1025 0.005137"/>
      <geometry>
        <mesh filename="$(find FINAL_description)/meshes/Arm_1_1.stl" scale="0.001 0.001 0.001"/>
      </geometry>
    </collision>
  </link>
  <link name="Gear_1_1">
    <inertial>
      <origin rpy="0 0 0" xyz="0.0005995518268453459 -2.4232014186886808e-08 0.07866273581028918"/>
      <mass value="9.880467825044573"/>
      <inertia ixx="0.1341" ixy="-0.0" ixz="-0.000641" iyy="0.139269" iyz="-0.0" izz="0.013058"/>
    </inertial>
    <visual>
      <origin rpy="0 0 0" xyz="-0.0295 -0.1025 -0.153863"/>
      <geometry>
        <mesh filename="$(find FINAL_description)/meshes/Gear_1_1.stl" scale="0.001 0.001 0.001"/>
      </geometry>
      <material name="grey"/>
    </visual>
    <collision>
      <origin rpy="0 0 0" xyz="-0.0295 -0.1025 -0.153863"/>
      <geometry>
        <mesh filename="$(find FINAL_description)/meshes/Gear_1_1.stl" scale="0.001 0.001 0.001"/>
      </geometry>
    </collision>
  </link>
  <link name="Gear_3,_UPDATED_1">
    <inertial>
      <origin rpy="0 0 0" xyz="0.10632233944315062 -3.750772539778957e-09 3.936726586550865e-05"/>
      <mass value="3.3142167062879557"/>
      <inertia ixx="0.002162" ixy="0.0" ixz="9e-06" iyy="0.049369" iyz="-0.0" izz="0.049579"/>
    </inertial>
    <visual>
      <origin rpy="0 0 0" xyz="-0.0295 -0.1025 -0.518363"/>
      <geometry>
        <mesh filename="$(find FINAL_description)/meshes/Gear_3,_UPDATED_1.stl" scale="0.001 0.001 0.001"/>
      </geometry>
      <material name="grey"/>
    </visual>
    <collision>
      <origin rpy="0 0 0" xyz="-0.0295 -0.1025 -0.518363"/>
      <geometry>
        <mesh filename="$(find FINAL_description)/meshes/Gear_3,_UPDATED_1.stl" scale="0.001 0.001 0.001"/>
      </geometry>
    </collision>
  </link>
  <link name="Manipulator3__2__1">
    <inertial>
      <origin rpy="0 0 0" xyz="0.0019402690204358697 -9.536742284765864e-09 -0.022194034609853808"/>
      <mass value="0.0043871469606408635"/>
      <inertia ixx="2e-06" ixy="-0.0" ixz="0.0" iyy="1e-06" iyz="0.0" izz="1e-06"/>
    </inertial>
    <visual>
      <origin rpy="0 0 0" xyz="-0.4145 -0.1025 -0.518363"/>
      <geometry>
        <mesh filename="$(find FINAL_description)/meshes/Manipulator3__2__1.stl" scale="0.001 0.001 0.001"/>
      </geometry>
      <material name="grey"/>
    </visual>
    <collision>
      <origin rpy="0 0 0" xyz="-0.4145 -0.1025 -0.518363"/>
      <geometry>
        <mesh filename="$(find FINAL_description)/meshes/Manipulator3__2__1.stl" scale="0.001 0.001 0.001"/>
      </geometry>
    </collision>
  </link>
  <joint name="Revolute 40" type="continuous">
    <origin rpy="0 0 0" xyz="0.0075 0.1025 -0.037395"/>
    <parent link="base_link"/>
    <child link="sun_connector_shaft_1"/>
    <axis xyz="-0.0 0.0 1.0"/>
  </joint>
  <joint name="Rigid 41" type="fixed">
    <origin rpy="0 0 0" xyz="0.0 0.0 0.03048"/>
    <parent link="sun_connector_shaft_1"/>
    <child link="Planetary_Gear_Arm_Connector,1_1"/>
  </joint>
  <joint name="Rigid 42" type="fixed">
    <origin rpy="0 0 0" xyz="0.0 0.0 0.001778"/>
    <parent link="Planetary_Gear_Arm_Connector,1_1"/>
    <child link="Arm_1_1"/>
  </joint>
  <joint name="Revolute 43" type="continuous">
    <origin rpy="0 0 0" xyz="0.022 0.0 0.159"/>
    <parent link="Arm_1_1"/>
    <child link="Gear_1_1"/>
    <axis xyz="-0.0 1.0 -0.0"/>
  </joint>
  <joint name="Revolute 44" type="continuous">
    <origin rpy="0 0 0" xyz="0.0 0.0 0.3645"/>
    <parent link="Gear_1_1"/>
    <child link="Gear_3,_UPDATED_1"/>
    <axis xyz="-0.0 1.0 -0.0"/>
  </joint>
  <joint name="Revolute 45" type="continuous">
    <origin rpy="0 0 0" xyz="0.385 0.0 0.0"/>
    <parent link="Gear_3,_UPDATED_1"/>
    <child link="Manipulator3__2__1"/>
    <axis xyz="-0.0 1.0 -0.0"/>
  </joint>
</robot>
